Workbook

Sheet Customer Names
A1: Customer ID | B1: name | I1: DATA TRANSFORMATION
A2: Id1 | B2: Hawks, Ms. Kelly
A3: Id2 | B3: Lehner, Mr. Matthew D | G3: 1) Split 'names' column in the "Costomer Names" Table into 3 meaningful columns: 'Title','First Name', and 'Last name'.
A4: Id3 | B4: Lu, Mr. Phil
A5: Id4 | B5: Osborne, Ms. Kelsey | H5: Customer ID | I5: Title | J5: First Name | K5: Last Name
A6: Id5 | B6: Kadala, Ms. Kristyn | H6: Id1 | I6: Ms | J6: Kelly | K6: Hawks
A7: Id6 | B7: Baker, Mr. Russell B. | H7: Id2 | I7: Mr | J7: Matthew D | K7: Lehner
A8: Id7 | B8: Macpherson, Mr. Scott | H8: Id3 | I8: Mr | J8: Phil | K8: Lu
A9: Id8 | B9: Hallman, Mr. Stephen | H9: Id4 | I9: Ms | J9: Kelsey | K9: Osborne
A10: Id9 | B10: Moran, Mr. Patrick R. | H10: Id5 | I10: Ms | J10: Kristyn | K10: Kadala
A11: Id10 | B11: Benner, Ms. Brooke N. | H11: Id6 | I11: Mr | J11: Russell B | K11: Baker
A12: Id11 | B12: Fierro Vargas, Ms. Paola Andrea | H12: Id7 | I12: Mr | J12: Scott | K12: Macpherson
A13: Id12 | B13: Franz, Mr. David | H13: Id8 | I13: Mr | J13: Stephen | K13: Hallman
A14: Id13 | B14: Foster, Mr. Wade | H14: Id9 | I14: Mr | J14: Patrick R | K14: Moran
A15: Id14 | B15: Tenorio, Mr. Franklin | H15: Id10 | I15: Ms | J15: Brooke N | K15: Benner
A16: Id15 | B16: Rios, Ms. Leilani M. | H16: Id11 | I16: Ms | J16: Paola Andrea | K16: Fierro Vargas
... A2336: Id2335 | B2336: German, Mr. Aaron K | H2336: Id2331 | I2336: Mr | J2336: Jordan | K2336: Brietzke
H2337: Id2332 | I2337: Mr | J2337: Juan D | K2337: Riveros Gonzalez
H2338: Id2333 | I2338: Ms | J2338: Julie | K2338: Albano
H2339: Id2334 | I2339: Mr | J2339: Evan P | K2339: Rosendahl
H2340: Id2335 | I2340: Mr | J2340: Aaron K | K2340: German

Sheet Hospitalisation Details
A1: Customer ID | B1: year | C1: YEAR (lookup) | D1: month | E1: MONTH (lookup) | F1: date | G1: Date of Birth | H1: children | I1: charges | J1: Charges ($) (lookup) | K1: Hospital tier | L1: Hospital tier (lookup) | M1: City tier | N1: City tier(lookup) | O1: State ID | P1: State ID (lookup) | Q1: Age (lookup)
A2: Id1 | B2: 1992 | C2: =IF(B2="?",ROUND(AVERAGE($B$2:$B$2336),0),B2) -> 1992 | D2: Jul | E2: =SUBSTITUTE(D2,"?","Sep") -> Jul | F2: 9 | G2: =DATE(C2,MONTH(E2&2),F2) -> 33794 | H2: 0 | I2: 563.84 | J2: 563.84 | K2: tier - 2 | L2: {=SUBSTITUTE(K2:K2344,"?","nil")} -> tier - 2 | M2: tier - 3 | N2: {=SUBSTITUTE(M2:M2344,"?","nil")} -> tier - 3 | O2: R1013 | P2: {=SUBSTITUTE(O2:O2336,"?","Unknown")} -> R1013 | Q2: =INT((TODAY()-G2)/365.25) -> 33 | V2: DATA CLEANING | AJ2: DATA CLEANING | AT2: DATA CLEANING | BD2: DATA TRANSFORMATION | BM2: DATA TRANSFORMATION | BT2: DATA TRANSFORMATION
A3: Id2 | B3: 1992 | C3: =IF(B3="?",ROUND(AVERAGE($B$2:$B$2336),0),B3) -> 1992 | D3: Nov | E3: =SUBSTITUTE(D3,"?","Sep") -> Nov | F3: 30 | G3: =DATE(C3,MONTH(E3&2),F3) -> 33938 | H3: 0 | I3: 570.62 | J3: 570.62 | K3: tier - 2 | L3: tier - 2 | M3: tier - 1 | N3: tier - 1 | O3: R1013 | P3: R1013 | Q3: =INT((TODAY()-G3)/365.25) -> 32
A4: Id3 | B4: 1993 | C4: =IF(B4="?",ROUND(AVERAGE($B$2:$B$2336),0),B4) -> 1993 | D4: Jun | E4: =SUBSTITUTE(D4,"?","Sep") -> Jun | F4: 30 | G4: =DATE(C4,MONTH(E4&2),F4) -> 34150 | H4: 0 | I4: 600 | J4: 600 | K4: tier - 2 | L4: tier - 2 | M4: tier - 1 | N4: tier - 1 | O4: R1013 | P4: R1013 | Q4: =INT((TODAY()-G4)/365.25) -> 32 | S4: 1) The Number of missing values in the Hospitalisation Details to contain "?" = | AC4: =COUNTIF(A2:O2336,"?") -> 8 | AF4: 3) Determine the most frequently occurring values in the ‘smoker’, 'Hospital tier' and 'City tier' | AQ4: 4) If any 'State ID' values are missing, consider filling them with 'Unknown' or using another | BA4: 6) Merge ‘year’, ‘month’ and ‘date’ columns in the “Hospitalization Details” Table into one | BK4: 7) Calculate the ‘Age’ of each customer based on their ‘Date of Birth’ and the date of | BT4: 8) Format ‘charges’ column as currency ($).
A5: Id4 | B5: 1992 | C5: =IF(B5="?",ROUND(AVERAGE($B$2:$B$2336),0),B5) -> 1992 | D5: Sep | E5: =SUBSTITUTE(D5,"?","Sep") -> Sep | F5: 13 | G5: =DATE(C5,MONTH(E5&2),F5) -> 33860 | H5: 0 | I5: 604.54 | J5: 604.54 | K5: tier - 3 | L5: tier - 3 | M5: tier - 3 | N5: tier - 3 | O5: R1013 | P5: R1013 | Q5: =INT((TODAY()-G5)/365.25) -> 33 | AF5: columns, and fill in the missing values accordingly. | AQ5: appropriate strategy. | BA5: column named ‘Date of Birth’ and format it in ‘DD-MMM-YYYY’ custom format. | BK5: collection of the dataset.
A6: Id5 | B6: 1998 | C6: =IF(B6="?",ROUND(AVERAGE($B$2:$B$2336),0),B6) -> 1998 | D6: Jul | E6: =SUBSTITUTE(D6,"?","Sep") -> Jul | F6: 27 | G6: =DATE(C6,MONTH(E6&2),F6) -> 36003 | H6: 0 | I6: 637.26 | J6: 637.26 | K6: tier - 3 | L6: tier - 3 | M6: tier - 3 | N6: tier - 3 | O6: R1013 | P6: R1013 | Q6: =INT((TODAY()-G6)/365.25) -> 27 | V6: DATA CLEANING
A7: Id6 | B7: 2001 | C7: =IF(B7="?",ROUND(AVERAGE($B$2:$B$2336),0),B7) -> 2001 | D7: Nov | E7: =SUBSTITUTE(D7,"?","Sep") -> Nov | F7: 20 | G7: =DATE(C7,MONTH(E7&2),F7) -> 37215 | H7: 0 | I7: 646.14 | J7: 646.14 | K7: tier - 3 | L7: tier - 3 | M7: tier - 3 | N7: tier - 3 | O7: R1012 | P7: R1012 | Q7: =INT((TODAY()-G7)/365.25) -> 23 | BM7: year | BN7: month | BO7: date | BP7: Date of Birth | BQ7: Age | BU7: charges | BV7: Charges ($)
A8: Id7 | B8: 1993 | C8: =IF(B8="?",ROUND(AVERAGE($B$2:$B$2336),0),B8) -> 1993 | D8: Jun | E8: =SUBSTITUTE(D8,"?","Sep") -> Jun | F8: 1 | G8: =DATE(C8,MONTH(E8&2),F8) -> 34121 | H8: 0 | I8: 650 | J8: 650 | K8: tier - 3 | L8: tier - 3 | M8: tier - 3 | N8: tier - 3 | O8: R1013 | P8: R1013 | Q8: =INT((TODAY()-G8)/365.25) -> 32 | S8: 2) Fill in the missing values of ‘month’ with Sep and ‘year’ with its average = | AC8: =AVERAGE(X13:X2347) -> 1982.8647 | AG8: Customer ID | AH8: smoker | AI8: Hospital tier | AJ8: City tier | AK8: Missing Values In "HT" | AL8: Missing Values In "CT" | AT8: State ID | AU8: Missing State ID | BD8: year | BE8: month | BF8: date | BG8: Date of Birth | BM8: 1992 | BN8: =SUBSTITUTE(E2,"?","Sep") -> Jul | BO8: 9 | BP8: =DATE(BM8,MONTH(5&BN8),BO8) -> 33794 | BQ8: =INT((TODAY()-BP8)/365.25) -> 33 | BU8: 563.84 | BV8: 563.84
A9: Id8 | B9: 1995 | C9: =IF(B9="?",ROUND(AVERAGE($B$2:$B$2336),0),B9) -> 1995 | D9: Jul | E9: =SUBSTITUTE(D9,"?","Sep") -> Jul | F9: 4 | G9: =DATE(C9,MONTH(E9&2),F9) -> 34884 | H9: 0 | I9: 650 | J9: 650 | K9: tier - 3 | L9: tier - 3 | M9: tier - 3 | N9: tier - 3 | O9: R1013 | P9: R1013 | Q9: =INT((TODAY()-G9)/365.25) -> 30 | S9: rounded to the nearest integer. = | AC9: =ROUND(1982.842,0) -> 1983 | AG9: Id1 | AH9: yes | AI9: tier - 2 | AJ9: tier - 3 | AK9: {=SUBSTITUTE(AI9:AI2343,"?","UNKNOWN")} -> tier - 2 | AL9: {=SUBSTITUTE(AJ9:AJ2343,"?","UNKNOWN")} -> tier - 3 | AT9: R1013 | AU9: {=SUBSTITUTE(AT9:AT2351,"?","Unknown")} -> R1013 | BD9: 1992 | BE9: =SUBSTITUTE(D2,"?","Sep") -> Jul | BF9: 9 | BG9: =DATE(BD9,MONTH(5&BE9),BF9) -> 33794 | BM9: 1992 | BN9: =SUBSTITUTE(E3,"?","Sep") -> Nov | BO9: 30 | BP9: =DATE(BM9,MONTH(5&BN9),BO9) -> 33938 | BQ9: =INT((TODAY()-BP9)/365.25) -> 32 | BU9: 570.62 | BV9: 570.62
A10: Id9 | B10: 2002 | C10: =IF(B10="?",ROUND(AVERAGE($B$2:$B$2336),0),B10) -> 2002 | D10: Nov | E10: =SUBSTITUTE(D10,"?","Sep") -> Nov | F10: 29 | G10: =DATE(C10,MONTH(E10&2),F10) -> 37589 | H10: 0 | I10: 668 | J10: 668 | K10: tier - 3 | L10: tier - 3 | M10: tier - 2 | N10: tier - 2 | O10: R1012 | P10: R1012 | Q10: =INT((TODAY()-G10)/365.25) -> 22 | AG10: Id2 | AH10: yes | AI10: tier - 2 | AJ10: tier - 1 | AK10: tier - 2 | AL10: tier - 1 | AT10: R1013 | AU10: R1013 | BD10: 1992 | BE10: =SUBSTITUTE(D3,"?","Sep") -> Nov | BF10: 30 | BG10: =DATE(BD10,MONTH(5&BE10),BF10) -> 33938 | BM10: 1993 | BN10: =SUBSTITUTE(E4,"?","Sep") -> Jun | BO10: 30 | BP10: =DATE(BM10,MONTH(5&BN10),BO10) -> 34150 | BQ10: =INT((TODAY()-BP10)/365.25) -> 32 | BU10: 600 | BV10: 600
A11: Id10 | B11: 1997 | C11: =IF(B11="?",ROUND(AVERAGE($B$2:$B$2336),0),B11) -> 1997 | D11: Nov | E11: =SUBSTITUTE(D11,"?","Sep") -> Nov | F11: 9 | G11: =DATE(C11,MONTH(E11&2),F11) -> 35743 | H11: 0 | I11: 670 | J11: 670 | K11: tier - 3 | L11: tier - 3 | M11: tier - 3 | N11: tier - 3 | O11: R1013 | P11: R1013 | Q11: =INT((TODAY()-G11)/365.25) -> 27 | AG11: Id3 | AH11: yes | AI11: tier - 2 | AJ11: tier - 1 | AK11: tier - 2 | AL11: tier - 1 | AT11: R1013 | AU11: R1013 | BD11: 1993 | BE11: =SUBSTITUTE(D4,"?","Sep") -> Jun | BF11: 30 | BG11: =DATE(BD11,MONTH(5&BE11),BF11) -> 34150 | BM11: 1992 | BN11: =SUBSTITUTE(E5,"?","Sep") -> Sep | BO11: 13 | BP11: =DATE(BM11,MONTH(5&BN11),BO11) -> 33860 | BQ11: =INT((TODAY()-BP11)/365.25) -> 33 | BU11: 604.54 | BV11: 604.54
A12: Id11 | B12: 2001 | C12: =IF(B12="?",ROUND(AVERAGE($B$2:$B$2336),0),B12) -> 2001 | D12: Sep | E12: =SUBSTITUTE(D12,"?","Sep") -> Sep | F12: 12 | G12: =DATE(C12,MONTH(E12&2),F12) -> 37146 | H12: 0 | I12: 687.54 | J12: 687.54 | K12: tier - 3 | L12: tier - 3 | M12: tier - 2 | N12: tier - 2 | O12: R1013 | P12: R1013 | Q12: =INT((TODAY()-G12)/365.25) -> 24 | U12: month | V12: MONTH | X12: year | AG12: Id4 | AH12: yes | AI12: tier - 3 | AJ12: tier - 3 | AK12: tier - 3 | AL12: tier - 3 | AT12: R1013 | AU12: R1013 | BD12: 1992 | BE12: =SUBSTITUTE(D5,"?","Sep") -> Sep | BF12: 13 | BG12: =DATE(BD12,MONTH(5&BE12),BF12) -> 33860 | BM12: 1998 | BN12: =SUBSTITUTE(E6,"?","Sep") -> Jul | BO12: 27 | BP12: =DATE(BM12,MONTH(5&BN12),BO12) -> 36003 | BQ12: =INT((TODAY()-BP12)/365.25) -> 27 | BU12: 637.26 | BV12: 637.26
A13: Id12 | B13: 1999 | C13: =IF(B13="?",ROUND(AVERAGE($B$2:$B$2336),0),B13) -> 1999 | D13: Dec | E13: =SUBSTITUTE(D13,"?","Sep") -> Dec | F13: 26 | G13: =DATE(C13,MONTH(E13&2),F13) -> 36520 | H13: 0 | I13: 700 | J13: 700 | K13: ? | L13: nil | M13: tier - 3 | N13: tier - 3 | O13: R1013 | P13: R1013 | Q13: =INT((TODAY()-G13)/365.25) -> 25 | U13: Jul | V13: =SUBSTITUTE(U13,"?","Sep") -> Jul | X13: =IF(B2="?",ROUND(AVERAGE($B$2:$B$2355),0),B2) -> 1992 | AG13: Id5 | AH13: yes | AI13: tier - 3 | AJ13: tier - 3 | AK13: tier - 3 | AL13: tier - 3 | AT13: R1013 | AU13: R1013 | BD13: 1998 | BE13: =SUBSTITUTE(D6,"?","Sep") -> Jul | BF13: 27 | BG13: =DATE(BD13,MONTH(5&BE13),BF13) -> 36003 | BM13: 2001 | BN13: =SUBSTITUTE(E7,"?","Sep") -> Nov | BO13: 20 | BP13: =DATE(BM13,MONTH(5&BN13),BO13) -> 37215 | BQ13: =INT((TODAY()-BP13)/365.25) -> 23 | BU13: 646.14 | BV13: 646.14
A14: Id13 | B14: 1999 | C14: =IF(B14="?",ROUND(AVERAGE($B$2:$B$2336),0),B14) -> 1999 | D14: Dec | E14: =SUBSTITUTE(D14,"?","Sep") -> Dec | F14: 14 | G14: =DATE(C14,MONTH(E14&2),F14) -> 36508 | H14: 0 | I14: 722.99 | J14: 722.99 | K14: tier - 3 | L14: tier - 3 | M14: tier - 1 | N14: tier - 1 | O14: R1013 | P14: R1013 | Q14: =INT((TODAY()-G14)/365.25) -> 25 | U14: Nov | V14: =SUBSTITUTE(U14,"?","Sep") -> Nov | X14: =IF(B3="?",ROUND(AVERAGE($B$2:$B$2355),0),B3) -> 1992 | AG14: Id6 | AH14: yes | AI14: tier - 3 | AJ14: tier - 3 | AK14: tier - 3 | AL14: tier - 3 | AT14: R1012 | AU14: R1012 | BD14: 2001 | BE14: =SUBSTITUTE(D7,"?","Sep") -> Nov | BF14: 20 | BG14: =DATE(BD14,MONTH(5&BE14),BF14) -> 37215 | BM14: 1993 | BN14: =SUBSTITUTE(E8,"?","Sep") -> Jun | BO14: 1 | BP14: =DATE(BM14,MONTH(5&BN14),BO14) -> 34121 | BQ14: =INT((TODAY()-BP14)/365.25) -> 32 | BU14: 650 | BV14: 650
A15: Id14 | B15: 2002 | C15: =IF(B15="?",ROUND(AVERAGE($B$2:$B$2336),0),B15) -> 2002 | D15: ? | E15: =SUBSTITUTE(D15,"?","Sep") -> Sep | F15: 19 | G15: =DATE(C15,MONTH(E15&2),F15) -> 37518 | H15: 0 | I15: 750 | J15: 750 | K15: tier - 3 | L15: tier - 3 | M15: tier - 1 | N15: tier - 1 | O15: R1012 | P15: R1012 | Q15: =INT((TODAY()-G15)/365.25) -> 23 | U15: Jun | V15: =SUBSTITUTE(U15,"?","Sep") -> Jun | X15: =IF(B4="?",ROUND(AVERAGE($B$2:$B$2355),0),B4) -> 1993 | AG15: Id7 | AH15: yes | AI15: tier - 3 | AJ15: tier - 3 | AK15: tier - 3 | AL15: tier - 3 | AT15: R1013 | AU15: R1013 | BD15: 1993 | BE15: =SUBSTITUTE(D8,"?","Sep") -> Jun | BF15: 1 | BG15: =DATE(BD15,MONTH(5&BE15),BF15) -> 34121 | BM15: 1995 | BN15: =SUBSTITUTE(E9,"?","Sep") -> Jul | BO15: 4 | BP15: =DATE(BM15,MONTH(5&BN15),BO15) -> 34884 | BQ15: =INT((TODAY()-BP15)/365.25) -> 30 | BU15: 650 | BV15: 650
A16: Id15 | B16: 1993 | C16: =IF(B16="?",ROUND(AVERAGE($B$2:$B$2336),0),B16) -> 1993 | D16: Aug | E16: =SUBSTITUTE(D16,"?","Sep") -> Aug | F16: 9 | G16: =DATE(C16,MONTH(E16&2),F16) -> 34190 | H16: 0 | I16: 760 | J16: 760 | K16: tier - 3 | L16: tier - 3 | M16: tier - 1 | N16: tier - 1 | O16: R1013 | P16: R1013 | Q16: =INT((TODAY()-G16)/365.25) -> 32 | U16: Sep | V16: =SUBSTITUTE(U16,"?","Sep") -> Sep | X16: =IF(B5="?",ROUND(AVERAGE($B$2:$B$2355),0),B5) -> 1992 | AG16: Id8 | AH16: yes | AI16: tier - 3 | AJ16: tier - 3 | AK16: tier - 3 | AL16: tier - 3 | AT16: R1013 | AU16: R1013 | BD16: 1995 | BE16: =SUBSTITUTE(D9,"?","Sep") -> Jul | BF16: 4 | BG16: =DATE(BD16,MONTH(5&BE16),BF16) -> 34884 | BM16: 2002 | BN16: =SUBSTITUTE(E10,"?","Sep") -> Nov | BO16: 29 | BP16: =DATE(BM16,MONTH(5&BN16),BO16) -> 37589 | BQ16: =INT((TODAY()-BP16)/365.25) -> 22 | BU16: 668 | BV16: 668
A17: Id16 | B17: 1996 | C17: =IF(B17="?",ROUND(AVERAGE($B$2:$B$2336),0),B17) -> 1996 | D17: Oct | E17: =SUBSTITUTE(D17,"?","Sep") -> Oct | F17: 22 | G17: =DATE(C17,MONTH(E17&2),F17) -> 35360 | H17: 0 | I17: 760 | J17: 760 | K17: tier - 3 | L17: tier - 3 | M17: tier - 3 | N17: tier - 3 | O17: R1013 | P17: R1013 | Q17: =INT((TODAY()-G17)/365.25) -> 29 | U17: Jul | V17: =SUBSTITUTE(U17,"?","Sep") -> Jul | X17: =IF(B6="?",ROUND(AVERAGE($B$2:$B$2355),0),B6) -> 1998 | AG17: Id9 | AH17: yes | AI17: tier - 3 | AJ17: tier - 2 | AK17: tier - 3 | AL17: tier - 2 | AT17: R1012 | AU17: R1012 | BD17: 2002 | BE17: =SUBSTITUTE(D10,"?","Sep") -> Nov | BF17: 29 | BG17: =DATE(BD17,MONTH(5&BE17),BF17) -> 37589 | BM17: 1997 | BN17: =SUBSTITUTE(E11,"?","Sep") -> Nov | BO17: 9 | BP17: =DATE(BM17,MONTH(5&BN17),BO17) -> 35743 | BQ17: =INT((TODAY()-BP17)/365.25) -> 27 | BU17: 670 | BV17: 670
A18: Id17 | B18: 1993 | C18: =IF(B18="?",ROUND(AVERAGE($B$2:$B$2336),0),B18) -> 1993 | D18: Jun | E18: =SUBSTITUTE(D18,"?","Sep") -> Jun | F18: 28 | G18: =DATE(C18,MONTH(E18&2),F18) -> 34148 | H18: 0 | I18: 770 | J18: 770 | K18: tier - 3 | L18: tier - 3 | M18: tier - 3 | N18: tier - 3 | O18: R1013 | P18: R1013 | Q18: =INT((TODAY()-G18)/365.25) -> 32 | U18: Nov | V18: =SUBSTITUTE(U18,"?","Sep") -> Nov | X18: =IF(B7="?",ROUND(AVERAGE($B$2:$B$2355),0),B7) -> 2001 | AG18: Id10 | AH18: yes | AI18: tier - 3 | AJ18: tier - 3 | AK18: tier - 3 | AL18: tier - 3 | AT18: R1013 | AU18: R1013 | BD18: 1997 | BE18: =SUBSTITUTE(D11,"?","Sep") -> Nov | BF18: 9 | BG18: =DATE(BD18,MONTH(5&BE18),BF18) -> 35743 | BM18: 2001 | BN18: =SUBSTITUTE(E12,"?","Sep") -> Sep | BO18: 12 | BP18: =DATE(BM18,MONTH(5&BN18),BO18) -> 37146 | BQ18: =INT((TODAY()-BP18)/365.25) -> 24 | BU18: 687.54 | BV18: 687.54
A19: Id18 | B19: 1996 | C19: =IF(B19="?",ROUND(AVERAGE($B$2:$B$2336),0),B19) -> 1996 | D19: ? | E19: =SUBSTITUTE(D19,"?","Sep") -> Sep | F19: 18 | G19: =DATE(C19,MONTH(E19&2),F19) -> 35326 | H19: 0 | I19: 770.38 | J19: 770.38 | K19: tier - 3 | L19: tier - 3 | M19: ? | N19: nil | O19: R1012 | P19: R1012 | Q19: =INT((TODAY()-G19)/365.25) -> 29 | U19: Jun | V19: =SUBSTITUTE(U19,"?","Sep") -> Jun | X19: =IF(B8="?",ROUND(AVERAGE($B$2:$B$2355),0),B8) -> 1993 | AG19: Id11 | AH19: yes | AI19: tier - 3 | AJ19: tier - 2 | AK19: tier - 3 | AL19: tier - 2 | AT19: R1013 | AU19: R1013 | BD19: 2001 | BE19: =SUBSTITUTE(D12,"?","Sep") -> Sep | BF19: 12 | BG19: =DATE(BD19,MONTH(5&BE19),BF19) -> 37146 | BM19: 1999 | BN19: =SUBSTITUTE(E13,"?","Sep") -> Dec | BO19: 26 | BP19: =DATE(BM19,MONTH(5&BN19),BO19) -> 36520 | BQ19: =INT((TODAY()-BP19)/365.25) -> 25 | BU19: 700 | BV19: 700
A20: Id19 | B20: 1995 | C20: =IF(B20="?",ROUND(AVERAGE($B$2:$B$2336),0),B20) -> 1995 | D20: Dec | E20: =SUBSTITUTE(D20,"?","Sep") -> Dec | F20: 7 | G20: =DATE(C20,MONTH(E20&2),F20) -> 35040 | H20: 0 | I20: 773.54 | J20: 773.54 | K20: tier - 3 | L20: tier - 3 | M20: tier - 2 | N20: tier - 2 | O20: R1013 | P20: R1013 | Q20: =INT((TODAY()-G20)/365.25) -> 29 | U20: Jul | V20: =SUBSTITUTE(U20,"?","Sep") -> Jul | X20: =IF(B9="?",ROUND(AVERAGE($B$2:$B$2355),0),B9) -> 1995 | AG20: Id12 | AH20: yes | AI20: ? | AJ20: tier - 3 | AK20: UNKNOWN | AL20: tier - 3 | AT20: R1013 | AU20: R1013 | BD20: 1999 | BE20: =SUBSTITUTE(D13,"?","Sep") -> Dec | BF20: 26 | BG20: =DATE(BD20,MONTH(5&BE20),BF20) -> 36520 | BM20: 1999 | BN20: =SUBSTITUTE(E14,"?","Sep") -> Dec | BO20: 14 | BP20: =DATE(BM20,MONTH(5&BN20),BO20) -> 36508 | BQ20: =INT((TODAY()-BP20)/365.25) -> 25 | BU20: 722.99 | BV20: 722.99
A21: Id20 | B21: 2004 | C21: =IF(B21="?",ROUND(AVERAGE($B$2:$B$2336),0),B21) -> 2004 | D21: Oct | E21: =SUBSTITUTE(D21,"?","Sep") -> Oct | F21: 7 | G21: =DATE(C21,MONTH(E21&2),F21) -> 38267 | H21: 0 | I21: 830.52 | J21: 830.52 | K21: tier - 3 | L21: tier - 3 | M21: tier - 2 | N21: tier - 2 | O21: R1011 | P21: R1011 | Q21: =INT((TODAY()-G21)/365.25) -> 21 | U21: Nov | V21: =SUBSTITUTE(U21,"?","Sep") -> Nov | X21: =IF(B10="?",ROUND(AVERAGE($B$2:$B$2355),0),B10) -> 2002 | AG21: Id13 | AH21: yes | AI21: tier - 3 | AJ21: tier - 1 | AK21: tier - 3 | AL21: tier - 1 | AT21: R1013 | AU21: R1013 | BD21: 1999 | BE21: =SUBSTITUTE(D14,"?","Sep") -> Dec | BF21: 14 | BG21: =DATE(BD21,MONTH(5&BE21),BF21) -> 36508 | BM21: 2002 | BN21: =SUBSTITUTE(E15,"?","Sep") -> Sep | BO21: 19 | BP21: =DATE(BM21,MONTH(5&BN21),BO21) -> 37518 | BQ21: =INT((TODAY()-BP21)/365.25) -> 23 | BU21: 750 | BV21: 750
A22: Id21 | B22: 2000 | C22: =IF(B22="?",ROUND(AVERAGE($B$2:$B$2336),0),B22) -> 2000 | D22: Nov | E22: =SUBSTITUTE(D22,"?","Sep") -> Nov | F22: 18 | G22: =DATE(C22,MONTH(E22&2),F22) -> 36848 | H22: 0 | I22: 865.41 | J22: 865.41 | K22: tier - 3 | L22: tier - 3 | M22: tier - 1 | N22: tier - 1 | O22: R1013 | P22: R1013 | Q22: =INT((TODAY()-G22)/365.25) -> 24 | U22: Nov | V22: =SUBSTITUTE(U22,"?","Sep") -> Nov | X22: =IF(B11="?",ROUND(AVERAGE($B$2:$B$2355),0),B11) -> 1997 | AG22: Id14 | AH22: yes | AI22: tier - 3 | AJ22: tier - 1 | AK22: tier - 3 | AL22: tier - 1 | AT22: R1012 | AU22: R1012 | BD22: 2002 | BE22: =SUBSTITUTE(D15,"?","Sep") -> Sep | BF22: 19 | BG22: =DATE(BD22,MONTH(5&BE22),BF22) -> 37518 | BM22: 1993 | BN22: =SUBSTITUTE(E16,"?","Sep") -> Aug | BO22: 9 | BP22: =DATE(BM22,MONTH(5&BN22),BO22) -> 34190 | BQ22: =INT((TODAY()-BP22)/365.25) -> 32 | BU22: 760 | BV22: 760
A23: Id22 | B23: 1993 | C23: =IF(B23="?",ROUND(AVERAGE($B$2:$B$2336),0),B23) -> 1993 | D23: Nov | E23: =SUBSTITUTE(D23,"?","Sep") -> Nov | F23: 27 | G23: =DATE(C23,MONTH(E23&2),F23) -> 34300 | H23: 0 | I23: 896.21 | J23: 896.21 | K23: tier - 3 | L23: tier - 3 | M23: tier - 1 | N23: tier - 1 | O23: R1013 | P23: R1013 | Q23: =INT((TODAY()-G23)/365.25) -> 31 | U23: Sep | V23: =SUBSTITUTE(U23,"?","Sep") -> Sep | X23: =IF(B12="?",ROUND(AVERAGE($B$2:$B$2355),0),B12) -> 2001 | AG23: Id15 | AH23: yes | AI23: tier - 3 | AJ23: tier - 1 | AK23: tier - 3 | AL23: tier - 1 | AT23: R1013 | AU23: R1013 | BD23: 1993 | BE23: =SUBSTITUTE(D16,"?","Sep") -> Aug | BF23: 9 | BG23: =DATE(BD23,MONTH(5&BE23),BF23) -> 34190 | BM23: 1996 | BN23: =SUBSTITUTE(E17,"?","Sep") -> Oct | BO23: 22 | BP23: =DATE(BM23,MONTH(5&BN23),BO23) -> 35360 | BQ23: =INT((TODAY()-BP23)/365.25) -> 29 | BU23: 760 | BV23: 760
A24: Id23 | B24: 1994 | C24: =IF(B24="?",ROUND(AVERAGE($B$2:$B$2336),0),B24) -> 1994 | D24: Oct | E24: =SUBSTITUTE(D24,"?","Sep") -> Oct | F24: 30 | G24: =DATE(C24,MONTH(E24&2),F24) -> 34637 | H24: 0 | I24: 915.07 | J24: 915.07 | K24: tier - 3 | L24: tier - 3 | M24: tier - 1 | N24: tier - 1 | O24: R1013 | P24: R1013 | Q24: =INT((TODAY()-G24)/365.25) -> 31 | U24: Dec | V24: =SUBSTITUTE(U24,"?","Sep") -> Dec | X24: =IF(B13="?",ROUND(AVERAGE($B$2:$B$2355),0),B13) -> 1999 | AG24: Id16 | AH24: yes | AI24: tier - 3 | AJ24: tier - 3 | AK24: tier - 3 | AL24: tier - 3 | AT24: R1013 | AU24: R1013 | BD24: 1996 | BE24: =SUBSTITUTE(D17,"?","Sep") -> Oct | BF24: 22 | BG24: =DATE(BD24,MONTH(5&BE24),BF24) -> 35360 | BM24: 1993 | BN24: =SUBSTITUTE(E18,"?","Sep") -> Jun | BO24: 28 | BP24: =DATE(BM24,MONTH(5&BN24),BO24) -> 34148 | BQ24: =INT((TODAY()-BP24)/365.25) -> 32 | BU24: 770 | BV24: 770
... A1050: Id1049 | B1050: 1977 | C1050: =IF(B1050="?",ROUND(AVERAGE($B$2:$B$2336),0),B1050) -> 1977 | D1050: Jul | E1050: =SUBSTITUTE(D1050,"?","Sep") -> Jul | F1050: 26 | G1050: =DATE(C1050,MONTH(E1050&2),F1050) -> 28332 | H1050: 2 | I1050: 8527.53 | J1050: 8527.53 | K1050: tier - 2 | L1050: tier - 2 | M1050: tier - 2 | N1050: tier - 2 | O1050: R1013 | P1050: R1013 | Q1050: =INT((TODAY()-G1050)/365.25) -> 48 | U1050: Sep | V1050: =SUBSTITUTE(U1050,"?","Sep") -> Sep | X1050: =IF(B1039="?",ROUND(AVERAGE($B$2:$B$2355),0),B1039) -> 1972 | AG1050: Id1042 | AH1050: No | AI1050: tier - 2 | AJ1050: tier - 3 | AK1050: tier - 2 | AL1050: tier - 3 | AT1050: R1011 | AU1050: R1011 | BD1050: 1972 | BE1050: =SUBSTITUTE(D1043,"?","Sep") -> Dec | BF1050: 26 | BG1050: =DATE(BD1050,MONTH(5&BE1050),BF1050) -> 26659 | BM1050: 1992 | BN1050: =SUBSTITUTE(E1044,"?","Sep") -> Sep | BO1050: 9 | BP1050: =DATE(BM1050,MONTH(5&BN1050),BO1050) -> 33856 | BQ1050: =INT((TODAY()-BP1050)/365.25) -> 33 | BU1050: 8466.35 | BV1050: 8466.35
A1051: Id1050 | B1051: ? | C1051: =IF(B1051="?",ROUND(AVERAGE($B$2:$B$2336),0),B1051) -> 1983 | D1051: Jul | E1051: =SUBSTITUTE(D1051,"?","Sep") -> Jul | F1051: 24 | G1051: =DATE(C1051,MONTH(E1051&2),F1051) -> 30521 | H1051: 0 | I1051: 8534.67 | J1051: 8534.67 | K1051: tier - 2 | L1051: tier - 2 | M1051: tier - 3 | N1051: tier - 3 | O1051: R1024 | P1051: R1024 | Q1051: =INT((TODAY()-G1051)/365.25) -> 42 | U1051: Sep | V1051: =SUBSTITUTE(U1051,"?","Sep") -> Sep | X1051: =IF(B1040="?",ROUND(AVERAGE($B$2:$B$2355),0),B1040) -> 1972 | AG1051: Id1043 | AH1051: No | AI1051: tier - 2 | AJ1051: tier - 2 | AK1051: tier - 2 | AL1051: tier - 2 | AT1051: R1012 | AU1051: R1012 | BD1051: 1992 | BE1051: =SUBSTITUTE(D1044,"?","Sep") -> Sep | BF1051: 9 | BG1051: =DATE(BD1051,MONTH(5&BE1051),BF1051) -> 33856 | BM1051: 1993 | BN1051: =SUBSTITUTE(E1045,"?","Sep") -> Nov | BO1051: 10 | BP1051: =DATE(BM1051,MONTH(5&BN1051),BO1051) -> 34283 | BQ1051: =INT((TODAY()-BP1051)/365.25) -> 31 | BU1051: 8471.65 | BV1051: 8471.65
A1052: Id1051 | B1052: 1981 | C1052: =IF(B1052="?",ROUND(AVERAGE($B$2:$B$2336),0),B1052) -> 1981 | D1052: Dec | E1052: =SUBSTITUTE(D1052,"?","Sep") -> Dec | F1052: 27 | G1052: =DATE(C1052,MONTH(E1052&2),F1052) -> 29947 | H1052: 3 | I1052: 8538.29 | J1052: 8538.29 | K1052: tier - 2 | L1052: tier - 2 | M1052: tier - 3 | N1052: tier - 3 | O1052: R1024 | P1052: R1024 | Q1052: =INT((TODAY()-G1052)/365.25) -> 43 | U1052: Jun | V1052: =SUBSTITUTE(U1052,"?","Sep") -> Jun | X1052: =IF(B1041="?",ROUND(AVERAGE($B$2:$B$2355),0),B1041) -> 1966 | AG1052: Id1044 | AH1052: No | AI1052: tier - 2 | AJ1052: tier - 1 | AK1052: tier - 2 | AL1052: tier - 1 | AT1052: R1012 | AU1052: R1012 | BD1052: 1993 | BE1052: =SUBSTITUTE(D1045,"?","Sep") -> Nov | BF1052: 10 | BG1052: =DATE(BD1052,MONTH(5&BE1052),BF1052) -> 34283 | BM1052: 1977 | BN1052: =SUBSTITUTE(E1046,"?","Sep") -> Dec | BO1052: 26 | BP1052: =DATE(BM1052,MONTH(5&BN1052),BO1052) -> 28485 | BQ1052: =INT((TODAY()-BP1052)/365.25) -> 47 | BU1052: 8515.76 | BV1052: 8515.76
A1053: Id1052 | B1053: 1975 | C1053: =IF(B1053="?",ROUND(AVERAGE($B$2:$B$2336),0),B1053) -> 1975 | D1053: Nov | E1053: =SUBSTITUTE(D1053,"?","Sep") -> Nov | F1053: 6 | G1053: =DATE(C1053,MONTH(E1053&2),F1053) -> 27704 | H1053: 1 | I1053: 8539.67 | J1053: 8539.67 | K1053: tier - 2 | L1053: tier - 2 | M1053: tier - 3 | N1053: tier - 3 | O1053: R1011 | P1053: R1011 | Q1053: =INT((TODAY()-G1053)/365.25) -> 49 | U1053: Jun | V1053: =SUBSTITUTE(U1053,"?","Sep") -> Jun | X1053: =IF(B1042="?",ROUND(AVERAGE($B$2:$B$2355),0),B1042) -> 1984 | AG1053: Id1045 | AH1053: No | AI1053: tier - 2 | AJ1053: tier - 2 | AK1053: tier - 2 | AL1053: tier - 2 | AT1053: R1013 | AU1053: R1013 | BD1053: 1977 | BE1053: =SUBSTITUTE(D1046,"?","Sep") -> Dec | BF1053: 26 | BG1053: =DATE(BD1053,MONTH(5&BE1053),BF1053) -> 28485 | BM1053: 1977 | BN1053: =SUBSTITUTE(E1047,"?","Sep") -> Jun | BO1053: 21 | BP1053: =DATE(BM1053,MONTH(5&BN1053),BO1053) -> 28297 | BQ1053: =INT((TODAY()-BP1053)/365.25) -> 48 | BU1053: 8516.83 | BV1053: 8516.83
A1054: Id1053 | B1054: ? | C1054: =IF(B1054="?",ROUND(AVERAGE($B$2:$B$2336),0),B1054) -> 1983 | D1054: Dec | E1054: =SUBSTITUTE(D1054,"?","Sep") -> Dec | F1054: 12 | G1054: =DATE(C1054,MONTH(E1054&2),F1054) -> 30662 | H1054: 1 | I1054: 8547.69 | J1054: 8547.69 | K1054: tier - 2 | L1054: tier - 2 | M1054: tier - 1 | N1054: tier - 1 | O1054: R1013 | P1054: R1013 | Q1054: =INT((TODAY()-G1054)/365.25) -> 41 | U1054: Dec | V1054: =SUBSTITUTE(U1054,"?","Sep") -> Dec | X1054: =IF(B1043="?",ROUND(AVERAGE($B$2:$B$2355),0),B1043) -> 1972 | AG1054: Id1046 | AH1054: No | AI1054: tier - 2 | AJ1054: tier - 1 | AK1054: tier - 2 | AL1054: tier - 1 | AT1054: R1013 | AU1054: R1013 | BD1054: 1977 | BE1054: =SUBSTITUTE(D1047,"?","Sep") -> Jun | BF1054: 21 | BG1054: =DATE(BD1054,MONTH(5&BE1054),BF1054) -> 28297 | BM1054: 1977 | BN1054: =SUBSTITUTE(E1048,"?","Sep") -> Dec | BO1054: 29 | BP1054: =DATE(BM1054,MONTH(5&BN1054),BO1054) -> 28488 | BQ1054: =INT((TODAY()-BP1054)/365.25) -> 47 | BU1054: 8520.03 | BV1054: 8520.03
A1055: Id1054 | B1055: 1975 | C1055: =IF(B1055="?",ROUND(AVERAGE($B$2:$B$2336),0),B1055) -> 1975 | D1055: Aug | E1055: =SUBSTITUTE(D1055,"?","Sep") -> Aug | F1055: 6 | G1055: =DATE(C1055,MONTH(E1055&2),F1055) -> 27612 | H1055: 1 | I1055: 8551.35 | J1055: 8551.35 | K1055: tier - 2 | L1055: tier - 2 | M1055: tier - 2 | N1055: tier - 2 | O1055: R1011 | P1055: R1011 | Q1055: =INT((TODAY()-G1055)/365.25) -> 50 | U1055: Sep | V1055: =SUBSTITUTE(U1055,"?","Sep") -> Sep | X1055: =IF(B1044="?",ROUND(AVERAGE($B$2:$B$2355),0),B1044) -> 1992 | AG1055: Id1047 | AH1055: No | AI1055: tier - 2 | AJ1055: tier - 3 | AK1055: tier - 2 | AL1055: tier - 3 | AT1055: R1011 | AU1055: R1011 | BD1055: 1977 | BE1055: =SUBSTITUTE(D1048,"?","Sep") -> Dec | BF1055: 29 | BG1055: =DATE(BD1055,MONTH(5&BE1055),BF1055) -> 28488 | BM1055: 1979 | BN1055: =SUBSTITUTE(E1049,"?","Sep") -> Aug | BO1055: 13 | BP1055: =DATE(BM1055,MONTH(5&BN1055),BO1055) -> 29080 | BQ1055: =INT((TODAY()-BP1055)/365.25) -> 46 | BU1055: 8522 | BV1055: 8522
A1056: Id1055 | B1056: 1975 | C1056: =IF(B1056="?",ROUND(AVERAGE($B$2:$B$2336),0),B1056) -> 1975 | D1056: Aug | E1056: =SUBSTITUTE(D1056,"?","Sep") -> Aug | F1056: 21 | G1056: =DATE(C1056,MONTH(E1056&2),F1056) -> 27627 | H1056: 1 | I1056: 8556.91 | J1056: 8556.91 | K1056: tier - 2 | L1056: tier - 2 | M1056: tier - 1 | N1056: tier - 1 | O1056: R1011 | P1056: R1011 | Q1056: =INT((TODAY()-G1056)/365.25) -> 50 | U1056: Nov | V1056: =SUBSTITUTE(U1056,"?","Sep") -> Nov | X1056: =IF(B1045="?",ROUND(AVERAGE($B$2:$B$2355),0),B1045) -> 1993 | AG1056: Id1048 | AH1056: No | AI1056: tier - 2 | AJ1056: tier - 2 | AK1056: tier - 2 | AL1056: tier - 2 | AT1056: R1011 | AU1056: R1011 | BD1056: 1979 | BE1056: =SUBSTITUTE(D1049,"?","Sep") -> Aug | BF1056: 13 | BG1056: =DATE(BD1056,MONTH(5&BE1056),BF1056) -> 29080 | BM1056: 1977 | BN1056: =SUBSTITUTE(E1050,"?","Sep") -> Jul | BO1056: 26 | BP1056: =DATE(BM1056,MONTH(5&BN1056),BO1056) -> 28332 | BQ1056: =INT((TODAY()-BP1056)/365.25) -> 48 | BU1056: 8527.53 | BV1056: 8527.53
A1057: Id1056 | B1057: 1988 | C1057: =IF(B1057="?",ROUND(AVERAGE($B$2:$B$2336),0),B1057) -> 1988 | D1057: Sep | E1057: =SUBSTITUTE(D1057,"?","Sep") -> Sep | F1057: 21 | G1057: =DATE(C1057,MONTH(E1057&2),F1057) -> 32407 | H1057: 3 | I1057: 8567.25 | J1057: 8567.25 | K1057: tier - 2 | L1057: tier - 2 | M1057: tier - 1 | N1057: tier - 1 | O1057: R1012 | P1057: R1012 | Q1057: =INT((TODAY()-G1057)/365.25) -> 37 | U1057: Dec | V1057: =SUBSTITUTE(U1057,"?","Sep") -> Dec | X1057: =IF(B1046="?",ROUND(AVERAGE($B$2:$B$2355),0),B1046) -> 1977 | AG1057: Id1049 | AH1057: No | AI1057: tier - 2 | AJ1057: tier - 2 | AK1057: tier - 2 | AL1057: tier - 2 | AT1057: R1013 | AU1057: R1013 | BD1057: 1977 | BE1057: =SUBSTITUTE(D1050,"?","Sep") -> Jul | BF1057: 26 | BG1057: =DATE(BD1057,MONTH(5&BE1057),BF1057) -> 28332 | BM1057: ? | BN1057: =SUBSTITUTE(E1051,"?","Sep") -> Jul | BO1057: 24 | BP1057: =DATE(BM1057,MONTH(5&BN1057),BO1057) -> #VALUE! | BQ1057: =INT((TODAY()-BP1057)/365.25) -> #VALUE! | BU1057: 8534.67 | BV1057: 8534.67
A1058: Id1057 | B1058: 1975 | C1058: =IF(B1058="?",ROUND(AVERAGE($B$2:$B$2336),0),B1058) -> 1975 | D1058: Sep | E1058: =SUBSTITUTE(D1058,"?","Sep") -> Sep | F1058: 26 | G1058: =DATE(C1058,MONTH(E1058&2),F1058) -> 27663 | H1058: 1 | I1058: 8569.86 | J1058: 8569.86 | K1058: tier - 2 | L1058: tier - 2 | M1058: tier - 3 | N1058: tier - 3 | O1058: R1013 | P1058: R1013 | Q1058: =INT((TODAY()-G1058)/365.25) -> 50 | U1058: Jun | V1058: =SUBSTITUTE(U1058,"?","Sep") -> Jun | X1058: =IF(B1047="?",ROUND(AVERAGE($B$2:$B$2355),0),B1047) -> 1977 | AG1058: Id1050 | AH1058: No | AI1058: tier - 2 | AJ1058: tier - 3 | AK1058: tier - 2 | AL1058: tier - 3 | AT1058: R1024 | AU1058: R1024 | BD1058: ? | BE1058: =SUBSTITUTE(D1051,"?","Sep") -> Jul | BF1058: 24 | BG1058: =DATE(BD1058,MONTH(5&BE1058),BF1058) -> #VALUE! | BM1058: 1981 | BN1058: =SUBSTITUTE(E1052,"?","Sep") -> Dec | BO1058: 27 | BP1058: =DATE(BM1058,MONTH(5&BN1058),BO1058) -> 29947 | BQ1058: =INT((TODAY()-BP1058)/365.25) -> 43 | BU1058: 8538.29 | BV1058: 8538.29
A1059: Id1058 | B1059: 1982 | C1059: =IF(B1059="?",ROUND(AVERAGE($B$2:$B$2336),0),B1059) -> 1982 | D1059: Dec | E1059: =SUBSTITUTE(D1059,"?","Sep") -> Dec | F1059: 6 | G1059: =DATE(C1059,MONTH(E1059&2),F1059) -> 30291 | H1059: 3 | I1059: 8572.04 | J1059: 8572.04 | K1059: tier - 2 | L1059: tier - 2 | M1059: tier - 2 | N1059: tier - 2 | O1059: R1021 | P1059: R1021 | Q1059: =INT((TODAY()-G1059)/365.25) -> 42 | U1059: Dec | V1059: =SUBSTITUTE(U1059,"?","Sep") -> Dec | X1059: =IF(B1048="?",ROUND(AVERAGE($B$2:$B$2355),0),B1048) -> 1977 | AG1059: Id1051 | AH1059: No | AI1059: tier - 2 | AJ1059: tier - 3 | AK1059: tier - 2 | AL1059: tier - 3 | AT1059: R1024 | AU1059: R1024 | BD1059: 1981 | BE1059: =SUBSTITUTE(D1052,"?","Sep") -> Dec | BF1059: 27 | BG1059: =DATE(BD1059,MONTH(5&BE1059),BF1059) -> 29947 | BM1059: 1975 | BN1059: =SUBSTITUTE(E1053,"?","Sep") -> Nov | BO1059: 6 | BP1059: =DATE(BM1059,MONTH(5&BN1059),BO1059) -> 27704 | BQ1059: =INT((TODAY()-BP1059)/365.25) -> 49 | BU1059: 8539.67 | BV1059: 8539.67
A1060: Id1059 | B1060: 1987 | C1060: =IF(B1060="?",ROUND(AVERAGE($B$2:$B$2336),0),B1060) -> 1987 | D1060: Nov | E1060: =SUBSTITUTE(D1060,"?","Sep") -> Nov | F1060: 11 | G1060: =DATE(C1060,MONTH(E1060&2),F1060) -> 32092 | H1060: 3 | I1060: 8573.3 | J1060: 8573.3 | K1060: tier - 2 | L1060: tier - 2 | M1060: tier - 2 | N1060: tier - 2 | O1060: R1021 | P1060: R1021 | Q1060: =INT((TODAY()-G1060)/365.25) -> 37 | U1060: Aug | V1060: =SUBSTITUTE(U1060,"?","Sep") -> Aug | X1060: =IF(B1049="?",ROUND(AVERAGE($B$2:$B$2355),0),B1049) -> 1979 | AG1060: Id1052 | AH1060: No | AI1060: tier - 2 | AJ1060: tier - 3 | AK1060: tier - 2 | AL1060: tier - 3 | AT1060: R1011 | AU1060: R1011 | BD1060: 1975 | BE1060: =SUBSTITUTE(D1053,"?","Sep") -> Nov | BF1060: 6 | BG1060: =DATE(BD1060,MONTH(5&BE1060),BF1060) -> 27704 | BM1060: ? | BN1060: =SUBSTITUTE(E1054,"?","Sep") -> Dec | BO1060: 12 | BP1060: =DATE(BM1060,MONTH(5&BN1060),BO1060) -> #VALUE! | BQ1060: =INT((TODAY()-BP1060)/365.25) -> #VALUE! | BU1060: 8547.69 | BV1060: 8547.69
A1061: Id1060 | B1061: 1983 | C1061: =IF(B1061="?",ROUND(AVERAGE($B$2:$B$2336),0),B1061) -> 1983 | D1061: Dec | E1061: =SUBSTITUTE(D1061,"?","Sep") -> Dec | F1061: 30 | G1061: =DATE(C1061,MONTH(E1061&2),F1061) -> 30680 | H1061: 5 | I1061: 8582.3 | J1061: 8582.3 | K1061: tier - 2 | L1061: tier - 2 | M1061: tier - 1 | N1061: tier - 1 | O1061: R1013 | P1061: R1013 | Q1061: =INT((TODAY()-G1061)/365.25) -> 41 | U1061: Jul | V1061: =SUBSTITUTE(U1061,"?","Sep") -> Jul | X1061: =IF(B1050="?",ROUND(AVERAGE($B$2:$B$2355),0),B1050) -> 1977 | AG1061: Id1053 | AH1061: No | AI1061: tier - 2 | AJ1061: tier - 1 | AK1061: tier - 2 | AL1061: tier - 1 | AT1061: R1013 | AU1061: R1013 | BD1061: ? | BE1061: =SUBSTITUTE(D1054,"?","Sep") -> Dec | BF1061: 12 | BG1061: =DATE(BD1061,MONTH(5&BE1061),BF1061) -> #VALUE! | BM1061: 1975 | BN1061: =SUBSTITUTE(E1055,"?","Sep") -> Aug | BO1061: 6 | BP1061: =DATE(BM1061,MONTH(5&BN1061),BO1061) -> 27612 | BQ1061: =INT((TODAY()-BP1061)/365.25) -> 50 | BU1061: 8551.35 | BV1061: 8551.35
A1062: Id1061 | B1062: 1983 | C1062: =IF(B1062="?",ROUND(AVERAGE($B$2:$B$2336),0),B1062) -> 1983 | D1062: Jul | E1062: =SUBSTITUTE(D1062,"?","Sep") -> Jul | F1062: 25 | G1062: =DATE(C1062,MONTH(E1062&2),F1062) -> 30522 | H1062: 5 | I1062: 8596.83 | J1062: 8596.83 | K1062: tier - 2 | L1062: tier - 2 | M1062: tier - 3 | N1062: tier - 3 | O1062: R1013 | P1062: R1013 | Q1062: =INT((TODAY()-G1062)/365.25) -> 42 | U1062: Jul | V1062: =SUBSTITUTE(U1062,"?","Sep") -> Jul | X1062: =IF(B1051="?",ROUND(AVERAGE($B$2:$B$2355),0),B1051) -> 1983 | AG1062: Id1054 | AH1062: No | AI1062: tier - 2 | AJ1062: tier - 2 | AK1062: tier - 2 | AL1062: tier - 2 | AT1062: R1011 | AU1062: R1011 | BD1062: 1975 | BE1062: =SUBSTITUTE(D1055,"?","Sep") -> Aug | BF1062: 6 | BG1062: =DATE(BD1062,MONTH(5&BE1062),BF1062) -> 27612 | BM1062: 1975 | BN1062: =SUBSTITUTE(E1056,"?","Sep") -> Aug | BO1062: 21 | BP1062: =DATE(BM1062,MONTH(5&BN1062),BO1062) -> 27627 | BQ1062: =INT((TODAY()-BP1062)/365.25) -> 50 | BU1062: 8556.91 | BV1062: 8556.91
A1063: Id1062 | B1063: 1973 | C1063: =IF(B1063="?",ROUND(AVERAGE($B$2:$B$2336),0),B1063) -> 1973 | D1063: Jul | E1063: =SUBSTITUTE(D1063,"?","Sep") -> Jul | F1063: 11 | G1063: =DATE(C1063,MONTH(E1063&2),F1063) -> 26856 | H1063: 0 | I1063: 8601.33 | J1063: 8601.33 | K1063: tier - 2 | L1063: tier - 2 | M1063: tier - 1 | N1063: tier - 1 | O1063: R1013 | P1063: R1013 | Q1063: =INT((TODAY()-G1063)/365.25) -> 52 | U1063: Dec | V1063: =SUBSTITUTE(U1063,"?","Sep") -> Dec | X1063: =IF(B1052="?",ROUND(AVERAGE($B$2:$B$2355),0),B1052) -> 1981 | AG1063: Id1055 | AH1063: No | AI1063: tier - 2 | AJ1063: tier - 1 | AK1063: tier - 2 | AL1063: tier - 1 | AT1063: R1011 | AU1063: R1011 | BD1063: 1975 | BE1063: =SUBSTITUTE(D1056,"?","Sep") -> Aug | BF1063: 21 | BG1063: =DATE(BD1063,MONTH(5&BE1063),BF1063) -> 27627 | BM1063: 1988 | BN1063: =SUBSTITUTE(E1057,"?","Sep") -> Sep | BO1063: 21 | BP1063: =DATE(BM1063,MONTH(5&BN1063),BO1063) -> 32407 | BQ1063: =INT((TODAY()-BP1063)/365.25) -> 37 | BU1063: 8567.25 | BV1063: 8567.25
A1064: Id1063 | B1064: 1977 | C1064: =IF(B1064="?",ROUND(AVERAGE($B$2:$B$2336),0),B1064) -> 1977 | D1064: Sep | E1064: =SUBSTITUTE(D1064,"?","Sep") -> Sep | F1064: 24 | G1064: =DATE(C1064,MONTH(E1064&2),F1064) -> 28392 | H1064: 2 | I1064: 8603.82 | J1064: 8603.82 | K1064: tier - 2 | L1064: tier - 2 | M1064: tier - 1 | N1064: tier - 1 | O1064: R1019 | P1064: R1019 | Q1064: =INT((TODAY()-G1064)/365.25) -> 48 | U1064: Nov | V1064: =SUBSTITUTE(U1064,"?","Sep") -> Nov | X1064: =IF(B1053="?",ROUND(AVERAGE($B$2:$B$2355),0),B1053) -> 1975 | AG1064: Id1056 | AH1064: No | AI1064: tier - 2 | AJ1064: tier - 1 | AK1064: tier - 2 | AL1064: tier - 1 | AT1064: R1012 | AU1064: R1012 | BD1064: 1988 | BE1064: =SUBSTITUTE(D1057,"?","Sep") -> Sep | BF1064: 21 | BG1064: =DATE(BD1064,MONTH(5&BE1064),BF1064) -> 32407 | BM1064: 1975 | BN1064: =SUBSTITUTE(E1058,"?","Sep") -> Sep | BO1064: 26 | BP1064: =DATE(BM1064,MONTH(5&BN1064),BO1064) -> 27663 | BQ1064: =INT((TODAY()-BP1064)/365.25) -> 50 | BU1064: 8569.86 | BV1064: 8569.86
A1065: Id1064 | B1065: 1977 | C1065: =IF(B1065="?",ROUND(AVERAGE($B$2:$B$2336),0),B1065) -> 1977 | D1065: Nov | E1065: =SUBSTITUTE(D1065,"?","Sep") -> Nov | F1065: 12 | G1065: =DATE(C1065,MONTH(E1065&2),F1065) -> 28441 | H1065: 2 | I1065: 8604.48 | J1065: 8604.48 | K1065: tier - 3 | L1065: tier - 3 | M1065: tier - 2 | N1065: tier - 2 | O1065: R1016 | P1065: R1016 | Q1065: =INT((TODAY()-G1065)/365.25) -> 47 | U1065: Dec | V1065: =SUBSTITUTE(U1065,"?","Sep") -> Dec | X1065: =IF(B1054="?",ROUND(AVERAGE($B$2:$B$2355),0),B1054) -> 1983 | AG1065: Id1057 | AH1065: No | AI1065: tier - 2 | AJ1065: tier - 3 | AK1065: tier - 2 | AL1065: tier - 3 | AT1065: R1013 | AU1065: R1013 | BD1065: 1975 | BE1065: =SUBSTITUTE(D1058,"?","Sep") -> Sep | BF1065: 26 | BG1065: =DATE(BD1065,MONTH(5&BE1065),BF1065) -> 27663 | BM1065: 1982 | BN1065: =SUBSTITUTE(E1059,"?","Sep") -> Dec | BO1065: 6 | BP1065: =DATE(BM1065,MONTH(5&BN1065),BO1065) -> 30291 | BQ1065: =INT((TODAY()-BP1065)/365.25) -> 42 | BU1065: 8572.04 | BV1065: 8572.04
...

Sheet Medical Examinations
A1: Customer ID | B1: BMI | C1: HBA1C | D1: Heart Issues | E1: Any Transplants | F1: Cancer history | G1: NumberOfMajorSurgeries | H1: NumberOfMajorSurgeries for vlookup | I1: smoker | J1: smoker column for lookup | K1: weight Status | L1: Diabetes Status
A2: Id1 | B2: 47.41 | C2: 7.47 | D2: No | E2: No | F2: No | G2: No major surgery | H2: 0 | I2: yes | J2: yes | K2: =IF(B2<18.5,"Under Weight",IF(B2<=24.9,"Normal Weight",IF(B2<=29.9,"Over Weight","Obesity"))) -> Obesity | L2: =IF(C2<5.7,"Normal",IF(C2<=6.4,"Prediabetes","Diabetes")) -> Diabetes | P2: DATA CLEANING | Z2: DATA TRANSFORMATION | AH2: DATA TRANSFORMATION | AO2: DATA TRANSFORMATION
A3: Id2 | B3: 30.36 | C3: 5.77 | D3: No | E3: No | F3: No | G3: No major surgery | H3: 0 | I3: yes | J3: yes | K3: =IF(B3<18.5,"Under Weight",IF(B3<=24.9,"Normal Weight",IF(B3<=29.9,"Over Weight","Obesity"))) -> Obesity | L3: =IF(C3<5.7,"Normal",IF(C3<=6.4,"Prediabetes","Diabetes")) -> Prediabetes
A4: Id3 | B4: 34.485 | C4: 11.87 | D4: yes | E4: No | F4: No | G4: 2 | H4: 2 | I4: yes | J4: yes | K4: =IF(B4<18.5,"Under Weight",IF(B4<=24.9,"Normal Weight",IF(B4<=29.9,"Over Weight","Obesity"))) -> Obesity | L4: =IF(C4<5.7,"Normal",IF(C4<=6.4,"Prediabetes","Diabetes")) -> Diabetes | M4: 1) The Number of missing values in the Medical Examination to contain ? with = | U4: =COUNTIF(A2:I2:I2336,"?") -> 2 | X4: 3) Check for inconsistencies in the 'Heart Issues' and 'smoker' columns and propose | AE4: 4) Create a new column named “Weight Status” that categorizes BMI into different | AM4: 5) Create a new column named “Diabetes Status” and fill it as per the information
A5: Id4 | B5: 38.095 | C5: 6.05 | D5: No | E5: No | F5: No | G5: No major surgery | H5: 0 | I5: yes | J5: yes | K5: =IF(B5<18.5,"Under Weight",IF(B5<=24.9,"Normal Weight",IF(B5<=29.9,"Over Weight","Obesity"))) -> Obesity | L5: =IF(C5<5.7,"Normal",IF(C5<=6.4,"Prediabetes","Diabetes")) -> Prediabetes | X5: corrective actions if necessary. | AE5: categories as below: | AM5: given below:
A6: Id5 | B6: 35.53 | C6: 5.45 | D6: No | E6: No | F6: No | G6: No major surgery | H6: 0 | I6: yes | J6: yes | K6: =IF(B6<18.5,"Under Weight",IF(B6<=24.9,"Normal Weight",IF(B6<=29.9,"Over Weight","Obesity"))) -> Obesity | L6: =IF(C6<5.7,"Normal",IF(C6<=6.4,"Prediabetes","Diabetes")) -> Normal
A7: Id6 | B7: 32.8 | C7: 6.59 | D7: No | E7: No | F7: No | G7: No major surgery | H7: 0 | I7: yes | J7: yes | K7: =IF(B7<18.5,"Under Weight",IF(B7<=24.9,"Normal Weight",IF(B7<=29.9,"Over Weight","Obesity"))) -> Obesity | L7: =IF(C7<5.7,"Normal",IF(C7<=6.4,"Prediabetes","Diabetes")) -> Diabetes | P7: DATA TRANSFORMATION | Y7: Customer ID | Z7: Heart Issues | AA7: smoker | AB7: Corretive "HI" column | AC7: Corrective "Smoker" column | AH7: BMI | AI7: Weight Status | AQ7: HBA1C | AR7: Diabetes Status
A8: Id7 | B8: 36.4 | C8: 6.07 | D8: No | E8: No | F8: No | G8: No major surgery | H8: 0 | I8: yes | J8: yes | K8: =IF(B8<18.5,"Under Weight",IF(B8<=24.9,"Normal Weight",IF(B8<=29.9,"Over Weight","Obesity"))) -> Obesity | L8: =IF(C8<5.7,"Normal",IF(C8<=6.4,"Prediabetes","Diabetes")) -> Prediabetes | Y8: Id1 | Z8: No | AA8: yes | AB8: =PROPER(Z8) -> No | AC8: =PROPER(AA8) -> Yes | AH8: Below 18.5 | AI8: Under Weight | AQ8: Below 5.7 | AR8: Normal
A9: Id8 | B9: 36.96 | C9: 7.93 | D9: No | E9: No | F9: No | G9: 3 | H9: 3 | I9: yes | J9: yes | K9: =IF(B9<18.5,"Under Weight",IF(B9<=24.9,"Normal Weight",IF(B9<=29.9,"Over Weight","Obesity"))) -> Obesity | L9: =IF(C9<5.7,"Normal",IF(C9<=6.4,"Prediabetes","Diabetes")) -> Diabetes | N9: 2) Convert the "NumberOfMajorSurgeries" column in the “Medical Examinations” Table to | Y9: Id2 | Z9: No | AA9: yes | AB9: =PROPER(Z9) -> No | AC9: =PROPER(AA9) -> Yes | AH9: 18.5 - 24.9 | AI9: Normal Weight | AQ9: 5.7 - 6.4 | AR9: Prediabetes
A10: Id9 | B10: 41.14 | C10: 9.58 | D10: yes | E10: No | F10: Yes | G10: 1 | H10: 1 | I10: yes | J10: yes | K10: =IF(B10<18.5,"Under Weight",IF(B10<=24.9,"Normal Weight",IF(B10<=29.9,"Over Weight","Obesity"))) -> Obesity | L10: =IF(C10<5.7,"Normal",IF(C10<=6.4,"Prediabetes","Diabetes")) -> Diabetes | N10: numerical data by replacing non-numeric characters with meaningful numerical values | Y10: Id3 | Z10: yes | AA10: yes | AB10: =PROPER(Z10) -> Yes | AC10: =PROPER(AA10) -> Yes | AH10: 25.0 - 29.9 | AI10: Over Weight | AQ10: 6.5 and Above | AR10: Diabetes
A11: Id10 | B11: 38.06 | C11: 10.79 | D11: No | E11: No | F11: No | G11: No major surgery | H11: 0 | I11: yes | J11: yes | K11: =IF(B11<18.5,"Under Weight",IF(B11<=24.9,"Normal Weight",IF(B11<=29.9,"Over Weight","Obesity"))) -> Obesity | L11: =IF(C11<5.7,"Normal",IF(C11<=6.4,"Prediabetes","Diabetes")) -> Diabetes | Y11: Id4 | Z11: No | AA11: yes | AB11: =PROPER(Z11) -> No | AC11: =PROPER(AA11) -> Yes | AH11: 30.0 and Above | AI11: Obesity
A12: Id11 | B12: 37.7 | C12: 5.96 | D12: yes | E12: No | F12: No | G12: 2 | H12: 2 | I12: yes | J12: yes | K12: =IF(B12<18.5,"Under Weight",IF(B12<=24.9,"Normal Weight",IF(B12<=29.9,"Over Weight","Obesity"))) -> Obesity | L12: =IF(C12<5.7,"Normal",IF(C12<=6.4,"Prediabetes","Diabetes")) -> Prediabetes | P12: NumberOfMajorSurgeries | Q12: NumberOfMajorSurgeries | Y12: Id5 | Z12: No | AA12: yes | AB12: =PROPER(Z12) -> No | AC12: =PROPER(AA12) -> Yes
A13: Id12 | B13: 42.13 | C13: 11.9 | D13: No | E13: No | F13: No | G13: No major surgery | H13: 0 | I13: yes | J13: yes | K13: =IF(B13<18.5,"Under Weight",IF(B13<=24.9,"Normal Weight",IF(B13<=29.9,"Over Weight","Obesity"))) -> Obesity | L13: =IF(C13<5.7,"Normal",IF(C13<=6.4,"Prediabetes","Diabetes")) -> Diabetes | P13: No major surgery | Q13: 0 | Y13: Id6 | Z13: No | AA13: yes | AB13: =PROPER(Z13) -> No | AC13: =PROPER(AA13) -> Yes | AG13: Customer ID | AH13: BMI | AI13: weight Status | AP13: Customer ID | AQ13: HBA1C | AR13: Diabetes Status
A14: Id13 | B14: 40.92 | C14: 8.41 | D14: No | E14: No | F14: No | G14: No major surgery | H14: 0 | I14: yes | J14: yes | K14: =IF(B14<18.5,"Under Weight",IF(B14<=24.9,"Normal Weight",IF(B14<=29.9,"Over Weight","Obesity"))) -> Obesity | L14: =IF(C14<5.7,"Normal",IF(C14<=6.4,"Prediabetes","Diabetes")) -> Diabetes | P14: No major surgery | Q14: 0 | Y14: Id7 | Z14: No | AA14: yes | AB14: =PROPER(Z14) -> No | AC14: =PROPER(AA14) -> Yes | AG14: Id1 | AH14: 47.41 | AI14: =IF(AH14<18.5,"Under Weight",IF(AH14<=24.9,"Normal Weight",IF(AH14<=29.9,"Over Weight","Obesity"))) -> Obesity | AP14: Id1 | AQ14: 7.47 | AR14: =IF(AQ14<5.7,"Normal",IF(AQ14<=6.4,"Prediabetes","Diabetes")) -> Diabetes
A15: Id14 | B15: 40.565 | C15: 7.02 | D15: No | E15: No | F15: No | G15: No major surgery | H15: 0 | I15: yes | J15: yes | K15: =IF(B15<18.5,"Under Weight",IF(B15<=24.9,"Normal Weight",IF(B15<=29.9,"Over Weight","Obesity"))) -> Obesity | L15: =IF(C15<5.7,"Normal",IF(C15<=6.4,"Prediabetes","Diabetes")) -> Diabetes | P15: 2 | Q15: 2 | Y15: Id8 | Z15: No | AA15: yes | AB15: =PROPER(Z15) -> No | AC15: =PROPER(AA15) -> Yes | AG15: Id2 | AH15: 30.36 | AI15: =IF(AH15<18.5,"Under Weight",IF(AH15<=24.9,"Normal Weight",IF(AH15<=29.9,"Over Weight","Obesity"))) -> Obesity | AP15: Id2 | AQ15: 5.77 | AR15: =IF(AQ15<5.7,"Normal",IF(AQ15<=6.5,"Prediabetes","Diabetes")) -> Prediabetes
A16: Id15 | B16: 36.385 | C16: 7.59 | D16: yes | E16: No | F16: No | G16: 2 | H16: 2 | I16: yes | J16: yes | K16: =IF(B16<18.5,"Under Weight",IF(B16<=24.9,"Normal Weight",IF(B16<=29.9,"Over Weight","Obesity"))) -> Obesity | L16: =IF(C16<5.7,"Normal",IF(C16<=6.4,"Prediabetes","Diabetes")) -> Diabetes | P16: No major surgery | Q16: 0 | Y16: Id9 | Z16: yes | AA16: yes | AB16: =PROPER(Z16) -> Yes | AC16: =PROPER(AA16) -> Yes | AG16: Id3 | AH16: 34.485 | AI16: =IF(AH16<18.5,"Under Weight",IF(AH16<=24.9,"Normal Weight",IF(AH16<=29.9,"Over Weight","Obesity"))) -> Obesity | AP16: Id3 | AQ16: 11.87 | AR16: =IF(AQ16<5.7,"Normal",IF(AQ16<=6.5,"Prediabetes","Diabetes")) -> Diabetes
A17: Id16 | B17: 39.9 | C17: 11.32 | D17: No | E17: No | F17: No | G17: No major surgery | H17: 0 | I17: yes | J17: yes | K17: =IF(B17<18.5,"Under Weight",IF(B17<=24.9,"Normal Weight",IF(B17<=29.9,"Over Weight","Obesity"))) -> Obesity | L17: =IF(C17<5.7,"Normal",IF(C17<=6.4,"Prediabetes","Diabetes")) -> Diabetes | P17: No major surgery | Q17: 0 | Y17: Id10 | Z17: No | AA17: yes | AB17: =PROPER(Z17) -> No | AC17: =PROPER(AA17) -> Yes | AG17: Id4 | AH17: 38.095 | AI17: =IF(AH17<18.5,"Under Weight",IF(AH17<=24.9,"Normal Weight",IF(AH17<=29.9,"Over Weight","Obesity"))) -> Obesity | AP17: Id4 | AQ17: 6.05 | AR17: =IF(AQ17<5.7,"Normal",IF(AQ17<=6.5,"Prediabetes","Diabetes")) -> Prediabetes
A18: Id17 | B18: 33.8 | C18: 7.67 | D18: No | E18: No | F18: No | G18: 3 | H18: 3 | I18: yes | J18: yes | K18: =IF(B18<18.5,"Under Weight",IF(B18<=24.9,"Normal Weight",IF(B18<=29.9,"Over Weight","Obesity"))) -> Obesity | L18: =IF(C18<5.7,"Normal",IF(C18<=6.4,"Prediabetes","Diabetes")) -> Diabetes | P18: No major surgery | Q18: 0 | Y18: Id11 | Z18: yes | AA18: yes | AB18: =PROPER(Z18) -> Yes | AC18: =PROPER(AA18) -> Yes | AG18: Id5 | AH18: 35.53 | AI18: =IF(AH18<18.5,"Under Weight",IF(AH18<=24.9,"Normal Weight",IF(AH18<=29.9,"Over Weight","Obesity"))) -> Obesity | AP18: Id5 | AQ18: 5.45 | AR18: =IF(AQ18<5.7,"Normal",IF(AQ18<=6.5,"Prediabetes","Diabetes")) -> Normal
A19: Id18 | B19: 36.765 | C19: 7.29 | D19: yes | E19: No | F19: Yes | G19: 1 | H19: 1 | I19: yes | J19: yes | K19: =IF(B19<18.5,"Under Weight",IF(B19<=24.9,"Normal Weight",IF(B19<=29.9,"Over Weight","Obesity"))) -> Obesity | L19: =IF(C19<5.7,"Normal",IF(C19<=6.4,"Prediabetes","Diabetes")) -> Diabetes | P19: No major surgery | Q19: 0 | Y19: Id12 | Z19: No | AA19: yes | AB19: =PROPER(Z19) -> No | AC19: =PROPER(AA19) -> Yes | AG19: Id6 | AH19: 32.8 | AI19: =IF(AH19<18.5,"Under Weight",IF(AH19<=24.9,"Normal Weight",IF(AH19<=29.9,"Over Weight","Obesity"))) -> Obesity | AP19: Id6 | AQ19: 6.59 | AR19: =IF(AQ19<5.7,"Normal",IF(AQ19<=6.5,"Prediabetes","Diabetes")) -> Diabetes
A20: Id19 | B20: 36.955 | C20: 4.72 | D20: yes | E20: No | F20: No | G20: 1 | H20: 1 | I20: yes | J20: yes | K20: =IF(B20<18.5,"Under Weight",IF(B20<=24.9,"Normal Weight",IF(B20<=29.9,"Over Weight","Obesity"))) -> Obesity | L20: =IF(C20<5.7,"Normal",IF(C20<=6.4,"Prediabetes","Diabetes")) -> Normal | P20: 3 | Q20: 3 | Y20: Id13 | Z20: No | AA20: yes | AB20: =PROPER(Z20) -> No | AC20: =PROPER(AA20) -> Yes | AG20: Id7 | AH20: 36.4 | AI20: =IF(AH20<18.5,"Under Weight",IF(AH20<=24.9,"Normal Weight",IF(AH20<=29.9,"Over Weight","Obesity"))) -> Obesity | AP20: Id7 | AQ20: 6.07 | AR20: =IF(AQ20<5.7,"Normal",IF(AQ20<=6.5,"Prediabetes","Diabetes")) -> Prediabetes
A21: Id20 | B21: 42.9 | C21: 11.41 | D21: No | E21: No | F21: No | G21: No major surgery | H21: 0 | I21: yes | J21: yes | K21: =IF(B21<18.5,"Under Weight",IF(B21<=24.9,"Normal Weight",IF(B21<=29.9,"Over Weight","Obesity"))) -> Obesity | L21: =IF(C21<5.7,"Normal",IF(C21<=6.4,"Prediabetes","Diabetes")) -> Diabetes | P21: 1 | Q21: 1 | Y21: Id14 | Z21: No | AA21: yes | AB21: =PROPER(Z21) -> No | AC21: =PROPER(AA21) -> Yes | AG21: Id8 | AH21: 36.96 | AI21: =IF(AH21<18.5,"Under Weight",IF(AH21<=24.9,"Normal Weight",IF(AH21<=29.9,"Over Weight","Obesity"))) -> Obesity | AP21: Id8 | AQ21: 7.93 | AR21: =IF(AQ21<5.7,"Normal",IF(AQ21<=6.5,"Prediabetes","Diabetes")) -> Diabetes
A22: Id21 | B22: 36.3 | C22: 11.5 | D22: yes | E22: No | F22: No | G22: 2 | H22: 2 | I22: yes | J22: yes | K22: =IF(B22<18.5,"Under Weight",IF(B22<=24.9,"Normal Weight",IF(B22<=29.9,"Over Weight","Obesity"))) -> Obesity | L22: =IF(C22<5.7,"Normal",IF(C22<=6.4,"Prediabetes","Diabetes")) -> Diabetes | P22: No major surgery | Q22: 0 | Y22: Id15 | Z22: yes | AA22: yes | AB22: =PROPER(Z22) -> Yes | AC22: =PROPER(AA22) -> Yes | AG22: Id9 | AH22: 41.14 | AI22: =IF(AH22<18.5,"Under Weight",IF(AH22<=24.9,"Normal Weight",IF(AH22<=29.9,"Over Weight","Obesity"))) -> Obesity | AP22: Id9 | AQ22: 9.58 | AR22: =IF(AQ22<5.7,"Normal",IF(AQ22<=6.5,"Prediabetes","Diabetes")) -> Diabetes
A23: Id22 | B23: 32.2 | C23: 6.22 | D23: yes | E23: No | F23: No | G23: 2 | H23: 2 | I23: yes | J23: yes | K23: =IF(B23<18.5,"Under Weight",IF(B23<=24.9,"Normal Weight",IF(B23<=29.9,"Over Weight","Obesity"))) -> Obesity | L23: =IF(C23<5.7,"Normal",IF(C23<=6.4,"Prediabetes","Diabetes")) -> Prediabetes | P23: 2 | Q23: 2 | Y23: Id16 | Z23: No | AA23: yes | AB23: =PROPER(Z23) -> No | AC23: =PROPER(AA23) -> Yes | AG23: Id10 | AH23: 38.06 | AI23: =IF(AH23<18.5,"Under Weight",IF(AH23<=24.9,"Normal Weight",IF(AH23<=29.9,"Over Weight","Obesity"))) -> Obesity | AP23: Id10 | AQ23: 10.79 | AR23: =IF(AQ23<5.7,"Normal",IF(AQ23<=6.5,"Prediabetes","Diabetes")) -> Diabetes
A24: Id23 | B24: 31.3 | C24: 11.38 | D24: No | E24: No | F24: No | G24: 3 | H24: 3 | I24: yes | J24: yes | K24: =IF(B24<18.5,"Under Weight",IF(B24<=24.9,"Normal Weight",IF(B24<=29.9,"Over Weight","Obesity"))) -> Obesity | L24: =IF(C24<5.7,"Normal",IF(C24<=6.4,"Prediabetes","Diabetes")) -> Diabetes | P24: No major surgery | Q24: 0 | Y24: Id17 | Z24: No | AA24: yes | AB24: =PROPER(Z24) -> No | AC24: =PROPER(AA24) -> Yes | AG24: Id11 | AH24: 37.7 | AI24: =IF(AH24<18.5,"Under Weight",IF(AH24<=24.9,"Normal Weight",IF(AH24<=29.9,"Over Weight","Obesity"))) -> Obesity | AP24: Id11 | AQ24: 5.96 | AR24: =IF(AQ24<5.7,"Normal",IF(AQ24<=6.5,"Prediabetes","Diabetes")) -> Prediabetes
A25: Id24 | B25: 41.8 | C25: 7.89 | D25: yes | E25: No | F25: No | G25: 2 | H25: 2 | I25: yes | J25: yes | K25: =IF(B25<18.5,"Under Weight",IF(B25<=24.9,"Normal Weight",IF(B25<=29.9,"Over Weight","Obesity"))) -> Obesity | L25: =IF(C25<5.7,"Normal",IF(C25<=6.4,"Prediabetes","Diabetes")) -> Diabetes | P25: No major surgery | Q25: 0 | Y25: Id18 | Z25: yes | AA25: yes | AB25: =PROPER(Z25) -> Yes | AC25: =PROPER(AA25) -> Yes | AG25: Id12 | AH25: 42.13 | AI25: =IF(AH25<18.5,"Under Weight",IF(AH25<=24.9,"Normal Weight",IF(AH25<=29.9,"Over Weight","Obesity"))) -> Obesity | AP25: Id12 | AQ25: 11.9 | AR25: =IF(AQ25<5.7,"Normal",IF(AQ25<=6.5,"Prediabetes","Diabetes")) -> Diabetes
A26: Id25 | B26: 35.09 | C26: 4.38 | D26: yes | E26: No | F26: No | G26: 2 | H26: 2 | I26: yes | J26: yes | K26: =IF(B26<18.5,"Under Weight",IF(B26<=24.9,"Normal Weight",IF(B26<=29.9,"Over Weight","Obesity"))) -> Obesity | L26: =IF(C26<5.7,"Normal",IF(C26<=6.4,"Prediabetes","Diabetes")) -> Normal | P26: No major surgery | Q26: 0 | Y26: Id19 | Z26: yes | AA26: yes | AB26: =PROPER(Z26) -> Yes | AC26: =PROPER(AA26) -> Yes | AG26: Id13 | AH26: 40.92 | AI26: =IF(AH26<18.5,"Under Weight",IF(AH26<=24.9,"Normal Weight",IF(AH26<=29.9,"Over Weight","Obesity"))) -> Obesity | AP26: Id13 | AQ26: 8.41 | AR26: =IF(AQ26<5.7,"Normal",IF(AQ26<=6.5,"Prediabetes","Diabetes")) -> Diabetes
A27: Id26 | B27: 33.88 | C27: 7.01 | D27: No | E27: No | F27: No | G27: 3 | H27: 3 | I27: yes | J27: yes | K27: =IF(B27<18.5,"Under Weight",IF(B27<=24.9,"Normal Weight",IF(B27<=29.9,"Over Weight","Obesity"))) -> Obesity | L27: =IF(C27<5.7,"Normal",IF(C27<=6.4,"Prediabetes","Diabetes")) -> Diabetes | P27: 2 | Q27: 2 | Y27: Id20 | Z27: No | AA27: yes | AB27: =PROPER(Z27) -> No | AC27: =PROPER(AA27) -> Yes | AG27: Id14 | AH27: 40.565 | AI27: =IF(AH27<18.5,"Under Weight",IF(AH27<=24.9,"Normal Weight",IF(AH27<=29.9,"Over Weight","Obesity"))) -> Obesity | AP27: Id14 | AQ27: 7.02 | AR27: =IF(AQ27<5.7,"Normal",IF(AQ27<=6.5,"Prediabetes","Diabetes")) -> Diabetes
A28: Id27 | B28: 30.875 | C28: 11.88 | D28: No | E28: No | F28: No | G28: No major surgery | H28: 0 | I28: yes | J28: yes | K28: =IF(B28<18.5,"Under Weight",IF(B28<=24.9,"Normal Weight",IF(B28<=29.9,"Over Weight","Obesity"))) -> Obesity | L28: =IF(C28<5.7,"Normal",IF(C28<=6.4,"Prediabetes","Diabetes")) -> Diabetes | P28: No major surgery | Q28: 0 | Y28: Id21 | Z28: yes | AA28: yes | AB28: =PROPER(Z28) -> Yes | AC28: =PROPER(AA28) -> Yes | AG28: Id15 | AH28: 36.385 | AI28: =IF(AH28<18.5,"Under Weight",IF(AH28<=24.9,"Normal Weight",IF(AH28<=29.9,"Over Weight","Obesity"))) -> Obesity | AP28: Id15 | AQ28: 7.59 | AR28: =IF(AQ28<5.7,"Normal",IF(AQ28<=6.5,"Prediabetes","Diabetes")) -> Diabetes
A29: Id28 | B29: 36.86 | C29: 5.19 | D29: yes | E29: No | F29: Yes | G29: 1 | H29: 1 | I29: yes | J29: yes | K29: =IF(B29<18.5,"Under Weight",IF(B29<=24.9,"Normal Weight",IF(B29<=29.9,"Over Weight","Obesity"))) -> Obesity | L29: =IF(C29<5.7,"Normal",IF(C29<=6.4,"Prediabetes","Diabetes")) -> Normal | P29: 3 | Q29: 3 | Y29: Id22 | Z29: yes | AA29: yes | AB29: =PROPER(Z29) -> Yes | AC29: =PROPER(AA29) -> Yes | AG29: Id16 | AH29: 39.9 | AI29: =IF(AH29<18.5,"Under Weight",IF(AH29<=24.9,"Normal Weight",IF(AH29<=29.9,"Over Weight","Obesity"))) -> Obesity | AP29: Id16 | AQ29: 11.32 | AR29: =IF(AQ29<5.7,"Normal",IF(AQ29<=6.5,"Prediabetes","Diabetes")) -> Diabetes
A30: Id29 | B30: 35.86 | C30: 6.74 | D30: yes | E30: No | F30: No | G30: 2 | H30: 2 | I30: yes | J30: yes | K30: =IF(B30<18.5,"Under Weight",IF(B30<=24.9,"Normal Weight",IF(B30<=29.9,"Over Weight","Obesity"))) -> Obesity | L30: =IF(C30<5.7,"Normal",IF(C30<=6.4,"Prediabetes","Diabetes")) -> Diabetes | P30: 1 | Q30: 1 | Y30: Id23 | Z30: No | AA30: yes | AB30: =PROPER(Z30) -> No | AC30: =PROPER(AA30) -> Yes | AG30: Id17 | AH30: 33.8 | AI30: =IF(AH30<18.5,"Under Weight",IF(AH30<=24.9,"Normal Weight",IF(AH30<=29.9,"Over Weight","Obesity"))) -> Obesity | AP30: Id17 | AQ30: 7.67 | AR30: =IF(AQ30<5.7,"Normal",IF(AQ30<=6.5,"Prediabetes","Diabetes")) -> Diabetes
A31: Id30 | B31: 37.05 | C31: 8.44 | D31: No | E31: No | F31: No | G31: No major surgery | H31: 0 | I31: yes | J31: yes | K31: =IF(B31<18.5,"Under Weight",IF(B31<=24.9,"Normal Weight",IF(B31<=29.9,"Over Weight","Obesity"))) -> Obesity | L31: =IF(C31<5.7,"Normal",IF(C31<=6.4,"Prediabetes","Diabetes")) -> Diabetes | P31: 1 | Q31: 1 | Y31: Id24 | Z31: yes | AA31: yes | AB31: =PROPER(Z31) -> Yes | AC31: =PROPER(AA31) -> Yes | AG31: Id18 | AH31: 36.765 | AI31: =IF(AH31<18.5,"Under Weight",IF(AH31<=24.9,"Normal Weight",IF(AH31<=29.9,"Over Weight","Obesity"))) -> Obesity | AP31: Id18 | AQ31: 7.29 | AR31: =IF(AQ31<5.7,"Normal",IF(AQ31<=6.5,"Prediabetes","Diabetes")) -> Diabetes
A32: Id31 | B32: 43.89 | C32: 8.71 | D32: No | E32: No | F32: No | G32: No major surgery | H32: 0 | I32: yes | J32: yes | K32: =IF(B32<18.5,"Under Weight",IF(B32<=24.9,"Normal Weight",IF(B32<=29.9,"Over Weight","Obesity"))) -> Obesity | L32: =IF(C32<5.7,"Normal",IF(C32<=6.4,"Prediabetes","Diabetes")) -> Diabetes | P32: No major surgery | Q32: 0 | Y32: Id25 | Z32: yes | AA32: yes | AB32: =PROPER(Z32) -> Yes | AC32: =PROPER(AA32) -> Yes | AG32: Id19 | AH32: 36.955 | AI32: =IF(AH32<18.5,"Under Weight",IF(AH32<=24.9,"Normal Weight",IF(AH32<=29.9,"Over Weight","Obesity"))) -> Obesity | AP32: Id19 | AQ32: 4.72 | AR32: =IF(AQ32<5.7,"Normal",IF(AQ32<=6.5,"Prediabetes","Diabetes")) -> Normal
A33: Id32 | B33: 42.35 | C33: 5.08 | D33: yes | E33: No | F33: No | G33: No major surgery | H33: 0 | I33: yes | J33: yes | K33: =IF(B33<18.5,"Under Weight",IF(B33<=24.9,"Normal Weight",IF(B33<=29.9,"Over Weight","Obesity"))) -> Obesity | L33: =IF(C33<5.7,"Normal",IF(C33<=6.4,"Prediabetes","Diabetes")) -> Normal | P33: 2 | Q33: 2 | Y33: Id26 | Z33: No | AA33: yes | AB33: =PROPER(Z33) -> No | AC33: =PROPER(AA33) -> Yes | AG33: Id20 | AH33: 42.9 | AI33: =IF(AH33<18.5,"Under Weight",IF(AH33<=24.9,"Normal Weight",IF(AH33<=29.9,"Over Weight","Obesity"))) -> Obesity | AP33: Id20 | AQ33: 11.41 | AR33: =IF(AQ33<5.7,"Normal",IF(AQ33<=6.5,"Prediabetes","Diabetes")) -> Diabetes
A34: Id33 | B34: 31.35 | C34: 6.86 | D34: No | E34: No | F34: No | G34: No major surgery | H34: 0 | I34: yes | J34: yes | K34: =IF(B34<18.5,"Under Weight",IF(B34<=24.9,"Normal Weight",IF(B34<=29.9,"Over Weight","Obesity"))) -> Obesity | L34: =IF(C34<5.7,"Normal",IF(C34<=6.4,"Prediabetes","Diabetes")) -> Diabetes | P34: 2 | Q34: 2 | Y34: Id27 | Z34: No | AA34: yes | AB34: =PROPER(Z34) -> No | AC34: =PROPER(AA34) -> Yes | AG34: Id21 | AH34: 36.3 | AI34: =IF(AH34<18.5,"Under Weight",IF(AH34<=24.9,"Normal Weight",IF(AH34<=29.9,"Over Weight","Obesity"))) -> Obesity | AP34: Id21 | AQ34: 11.5 | AR34: =IF(AQ34<5.7,"Normal",IF(AQ34<=6.5,"Prediabetes","Diabetes")) -> Diabetes
A35: Id34 | B35: 47.6 | C35: 5.95 | D35: yes | E35: No | F35: No | G35: No major surgery | H35: 0 | I35: yes | J35: yes | K35: =IF(B35<18.5,"Under Weight",IF(B35<=24.9,"Normal Weight",IF(B35<=29.9,"Over Weight","Obesity"))) -> Obesity | L35: =IF(C35<5.7,"Normal",IF(C35<=6.4,"Prediabetes","Diabetes")) -> Prediabetes | P35: 3 | Q35: 3 | Y35: Id28 | Z35: yes | AA35: yes | AB35: =PROPER(Z35) -> Yes | AC35: =PROPER(AA35) -> Yes | AG35: Id22 | AH35: 32.2 | AI35: =IF(AH35<18.5,"Under Weight",IF(AH35<=24.9,"Normal Weight",IF(AH35<=29.9,"Over Weight","Obesity"))) -> Obesity | AP35: Id22 | AQ35: 6.22 | AR35: =IF(AQ35<5.7,"Normal",IF(AQ35<=6.5,"Prediabetes","Diabetes")) -> Prediabetes
A36: Id35 | B36: 46.2 | C36: 6.09 | D36: No | E36: No | F36: Yes | G36: 1 | H36: 1 | I36: yes | J36: yes | K36: =IF(B36<18.5,"Under Weight",IF(B36<=24.9,"Normal Weight",IF(B36<=29.9,"Over Weight","Obesity"))) -> Obesity | L36: =IF(C36<5.7,"Normal",IF(C36<=6.4,"Prediabetes","Diabetes")) -> Prediabetes | P36: 2 | Q36: 2 | Y36: Id29 | Z36: yes | AA36: yes | AB36: =PROPER(Z36) -> Yes | AC36: =PROPER(AA36) -> Yes | AG36: Id23 | AH36: 31.3 | AI36: =IF(AH36<18.5,"Under Weight",IF(AH36<=24.9,"Normal Weight",IF(AH36<=29.9,"Over Weight","Obesity"))) -> Obesity | AP36: Id23 | AQ36: 11.38 | AR36: =IF(AQ36<5.7,"Normal",IF(AQ36<=6.5,"Prediabetes","Diabetes")) -> Diabetes
A37: Id36 | B37: 32.015 | C37: 11.75 | D37: No | E37: No | F37: No | G37: No major surgery | H37: 0 | I37: yes | J37: yes | K37: =IF(B37<18.5,"Under Weight",IF(B37<=24.9,"Normal Weight",IF(B37<=29.9,"Over Weight","Obesity"))) -> Obesity | L37: =IF(C37<5.7,"Normal",IF(C37<=6.4,"Prediabetes","Diabetes")) -> Diabetes | P37: 2 | Q37: 2 | Y37: Id30 | Z37: No | AA37: yes | AB37: =PROPER(Z37) -> No | AC37: =PROPER(AA37) -> Yes | AG37: Id24 | AH37: 41.8 | AI37: =IF(AH37<18.5,"Under Weight",IF(AH37<=24.9,"Normal Weight",IF(AH37<=29.9,"Over Weight","Obesity"))) -> Obesity | AP37: Id24 | AQ37: 7.89 | AR37: =IF(AQ37<5.7,"Normal",IF(AQ37<=6.5,"Prediabetes","Diabetes")) -> Diabetes
A38: Id37 | B38: 40.565 | C38: 7.37 | D38: No | E38: No | F38: No | G38: No major surgery | H38: 0 | I38: yes | J38: yes | K38: =IF(B38<18.5,"Under Weight",IF(B38<=24.9,"Normal Weight",IF(B38<=29.9,"Over Weight","Obesity"))) -> Obesity | L38: =IF(C38<5.7,"Normal",IF(C38<=6.4,"Prediabetes","Diabetes")) -> Diabetes | P38: 3 | Q38: 3 | Y38: Id31 | Z38: No | AA38: yes | AB38: =PROPER(Z38) -> No | AC38: =PROPER(AA38) -> Yes | AG38: Id25 | AH38: 35.09 | AI38: =IF(AH38<18.5,"Under Weight",IF(AH38<=24.9,"Normal Weight",IF(AH38<=29.9,"Over Weight","Obesity"))) -> Obesity | AP38: Id25 | AQ38: 4.38 | AR38: =IF(AQ38<5.7,"Normal",IF(AQ38<=6.5,"Prediabetes","Diabetes")) -> Normal
A39: Id38 | B39: 32.45 | C39: 11.91 | D39: No | E39: No | F39: No | G39: No major surgery | H39: 0 | I39: yes | J39: yes | K39: =IF(B39<18.5,"Under Weight",IF(B39<=24.9,"Normal Weight",IF(B39<=29.9,"Over Weight","Obesity"))) -> Obesity | L39: =IF(C39<5.7,"Normal",IF(C39<=6.4,"Prediabetes","Diabetes")) -> Diabetes | P39: No major surgery | Q39: 0 | Y39: Id32 | Z39: yes | AA39: yes | AB39: =PROPER(Z39) -> Yes | AC39: =PROPER(AA39) -> Yes | AG39: Id26 | AH39: 33.88 | AI39: =IF(AH39<18.5,"Under Weight",IF(AH39<=24.9,"Normal Weight",IF(AH39<=29.9,"Over Weight","Obesity"))) -> Obesity | AP39: Id26 | AQ39: 7.01 | AR39: =IF(AQ39<5.7,"Normal",IF(AQ39<=6.5,"Prediabetes","Diabetes")) -> Diabetes
